[2024-12-05T15:24:08.786+0100] {local_task_job_runner.py:123} INFO - ::group::Pre task execution logs
[2024-12-05T15:24:08.789+0100] {taskinstance.py:2613} INFO - Dependencies all met for dep_context=non-requeueable deps ti=<TaskInstance: data_warehouse_etl.load_fact_table manual__2024-12-05T14:18:57.766135+00:00 [queued]>
[2024-12-05T15:24:08.792+0100] {taskinstance.py:2613} INFO - Dependencies all met for dep_context=requeueable deps ti=<TaskInstance: data_warehouse_etl.load_fact_table manual__2024-12-05T14:18:57.766135+00:00 [queued]>
[2024-12-05T15:24:08.792+0100] {taskinstance.py:2866} INFO - Starting attempt 2 of 2
[2024-12-05T15:24:08.797+0100] {taskinstance.py:2889} INFO - Executing <Task(PythonOperator): load_fact_table> on 2024-12-05 14:18:57.766135+00:00
[2024-12-05T15:24:08.800+0100] {standard_task_runner.py:72} INFO - Started process 20546 to run task
[2024-12-05T15:24:08.804+0100] {standard_task_runner.py:104} INFO - Running: ['airflow', 'tasks', 'run', 'data_warehouse_etl', 'load_fact_table', 'manual__2024-12-05T14:18:57.766135+00:00', '--job-id', '138', '--raw', '--subdir', 'DAGS_FOLDER/dim_process.py', '--cfg-path', '/var/folders/4k/bhptqqm131v6f034phck6fc80000gn/T/tmpxryln5fo']
[2024-12-05T15:24:08.806+0100] {standard_task_runner.py:105} INFO - Job 138: Subtask load_fact_table
[2024-12-05T15:24:08.829+0100] {task_command.py:467} INFO - Running <TaskInstance: data_warehouse_etl.load_fact_table manual__2024-12-05T14:18:57.766135+00:00 [running]> on host sijibomis-mbp
[2024-12-05T15:24:08.853+0100] {taskinstance.py:3132} INFO - Exporting env vars: AIRFLOW_CTX_DAG_OWNER='data_engineering' AIRFLOW_CTX_DAG_ID='data_warehouse_etl' AIRFLOW_CTX_TASK_ID='load_fact_table' AIRFLOW_CTX_EXECUTION_DATE='2024-12-05T14:18:57.766135+00:00' AIRFLOW_CTX_TRY_NUMBER='2' AIRFLOW_CTX_DAG_RUN_ID='manual__2024-12-05T14:18:57.766135+00:00'
[2024-12-05T15:24:08.853+0100] {taskinstance.py:731} INFO - ::endgroup::
[2024-12-05T15:24:08.958+0100] {logging_mixin.py:190} WARNING - /Users/sijibomijoshua/airflow/dags/dim_process.py:146 UserWarning: pandas only supports SQLAlchemy connectable (engine/connection) or database string URI or sqlite3 DBAPI2 connection. Other DBAPI2 objects are not tested. Please consider using SQLAlchemy.
[2024-12-05T15:24:08.989+0100] {python.py:240} INFO - Done. Returned value was: None
[2024-12-05T15:24:08.992+0100] {taskinstance.py:340} INFO - ::group::Post task execution logs
[2024-12-05T15:24:08.993+0100] {taskinstance.py:352} INFO - Marking task as SUCCESS. dag_id=data_warehouse_etl, task_id=load_fact_table, run_id=manual__2024-12-05T14:18:57.766135+00:00, execution_date=20241205T141857, start_date=20241205T142408, end_date=20241205T142408
[2024-12-05T15:24:09.036+0100] {local_task_job_runner.py:266} INFO - Task exited with return code 0
[2024-12-05T15:24:09.042+0100] {taskinstance.py:3895} INFO - 0 downstream tasks scheduled from follow-on schedule check
[2024-12-05T15:24:09.042+0100] {local_task_job_runner.py:245} INFO - ::endgroup::
