[2024-12-05T15:03:12.875+0100] {local_task_job_runner.py:123} INFO - ::group::Pre task execution logs
[2024-12-05T15:03:12.888+0100] {taskinstance.py:2613} INFO - Dependencies all met for dep_context=non-requeueable deps ti=<TaskInstance: data_warehouse_etl.load_fact_table manual__2024-12-05T13:58:01.600232+00:00 [queued]>
[2024-12-05T15:03:12.891+0100] {taskinstance.py:2613} INFO - Dependencies all met for dep_context=requeueable deps ti=<TaskInstance: data_warehouse_etl.load_fact_table manual__2024-12-05T13:58:01.600232+00:00 [queued]>
[2024-12-05T15:03:12.891+0100] {taskinstance.py:2866} INFO - Starting attempt 2 of 2
[2024-12-05T15:03:12.896+0100] {taskinstance.py:2889} INFO - Executing <Task(PythonOperator): load_fact_table> on 2024-12-05 13:58:01.600232+00:00
[2024-12-05T15:03:12.900+0100] {standard_task_runner.py:72} INFO - Started process 89939 to run task
[2024-12-05T15:03:12.903+0100] {standard_task_runner.py:104} INFO - Running: ['airflow', 'tasks', 'run', 'data_warehouse_etl', 'load_fact_table', 'manual__2024-12-05T13:58:01.600232+00:00', '--job-id', '113', '--raw', '--subdir', 'DAGS_FOLDER/dim_process.py', '--cfg-path', '/var/folders/4k/bhptqqm131v6f034phck6fc80000gn/T/tmpef54rdvv']
[2024-12-05T15:03:12.904+0100] {standard_task_runner.py:105} INFO - Job 113: Subtask load_fact_table
[2024-12-05T15:03:12.930+0100] {task_command.py:467} INFO - Running <TaskInstance: data_warehouse_etl.load_fact_table manual__2024-12-05T13:58:01.600232+00:00 [running]> on host sijibomis-mbp
[2024-12-05T15:03:12.950+0100] {taskinstance.py:3132} INFO - Exporting env vars: AIRFLOW_CTX_DAG_OWNER='data_engineering' AIRFLOW_CTX_DAG_ID='data_warehouse_etl' AIRFLOW_CTX_TASK_ID='load_fact_table' AIRFLOW_CTX_EXECUTION_DATE='2024-12-05T13:58:01.600232+00:00' AIRFLOW_CTX_TRY_NUMBER='2' AIRFLOW_CTX_DAG_RUN_ID='manual__2024-12-05T13:58:01.600232+00:00'
[2024-12-05T15:03:12.951+0100] {taskinstance.py:731} INFO - ::endgroup::
[2024-12-05T15:03:13.059+0100] {dim_process.py:146} ERROR - Error loading fact table: 'client'
[2024-12-05T15:03:13.060+0100] {taskinstance.py:3311} ERROR - Task failed with exception
Traceback (most recent call last):
  File "/Users/sijibomijoshua/airflow/airflow_env/lib/python3.11/site-packages/airflow/models/taskinstance.py", line 767, in _execute_task
    result = _execute_callable(context=context, **execute_callable_kwargs)
             ^^^^^^^^^^^^^^^^^^^^^^^^^^^^^^^^^^^^^^^^^^^^^^^^^^^^^^^^^^^^^
  File "/Users/sijibomijoshua/airflow/airflow_env/lib/python3.11/site-packages/airflow/models/taskinstance.py", line 733, in _execute_callable
    return ExecutionCallableRunner(
           ^^^^^^^^^^^^^^^^^^^^^^^^
  File "/Users/sijibomijoshua/airflow/airflow_env/lib/python3.11/site-packages/airflow/utils/operator_helpers.py", line 252, in run
    return self.func(*args, **kwargs)
           ^^^^^^^^^^^^^^^^^^^^^^^^^^
  File "/Users/sijibomijoshua/airflow/airflow_env/lib/python3.11/site-packages/airflow/models/baseoperator.py", line 417, in wrapper
    return func(self, *args, **kwargs)
           ^^^^^^^^^^^^^^^^^^^^^^^^^^^
  File "/Users/sijibomijoshua/airflow/airflow_env/lib/python3.11/site-packages/airflow/operators/python.py", line 238, in execute
    return_value = self.execute_callable()
                   ^^^^^^^^^^^^^^^^^^^^^^^
  File "/Users/sijibomijoshua/airflow/airflow_env/lib/python3.11/site-packages/airflow/operators/python.py", line 256, in execute_callable
    return runner.run(*self.op_args, **self.op_kwargs)
           ^^^^^^^^^^^^^^^^^^^^^^^^^^^^^^^^^^^^^^^^^^^
  File "/Users/sijibomijoshua/airflow/airflow_env/lib/python3.11/site-packages/airflow/utils/operator_helpers.py", line 252, in run
    return self.func(*args, **kwargs)
           ^^^^^^^^^^^^^^^^^^^^^^^^^^
  File "/Users/sijibomijoshua/airflow/dags/dim_process.py", line 147, in load_fact_table
    raise e
  File "/Users/sijibomijoshua/airflow/dags/dim_process.py", line 123, in load_fact_table
    merged_df = merged_df.merge(
                ^^^^^^^^^^^^^^^^
  File "/Users/sijibomijoshua/airflow/airflow_env/lib/python3.11/site-packages/pandas/core/frame.py", line 10832, in merge
    return merge(
           ^^^^^^
  File "/Users/sijibomijoshua/airflow/airflow_env/lib/python3.11/site-packages/pandas/core/reshape/merge.py", line 170, in merge
    op = _MergeOperation(
         ^^^^^^^^^^^^^^^^
  File "/Users/sijibomijoshua/airflow/airflow_env/lib/python3.11/site-packages/pandas/core/reshape/merge.py", line 794, in __init__
    ) = self._get_merge_keys()
        ^^^^^^^^^^^^^^^^^^^^^^
  File "/Users/sijibomijoshua/airflow/airflow_env/lib/python3.11/site-packages/pandas/core/reshape/merge.py", line 1310, in _get_merge_keys
    left_keys.append(left._get_label_or_level_values(lk))
                     ^^^^^^^^^^^^^^^^^^^^^^^^^^^^^^^^^^^
  File "/Users/sijibomijoshua/airflow/airflow_env/lib/python3.11/site-packages/pandas/core/generic.py", line 1911, in _get_label_or_level_values
    raise KeyError(key)
KeyError: 'client'
[2024-12-05T15:03:13.070+0100] {taskinstance.py:1225} INFO - Marking task as FAILED. dag_id=data_warehouse_etl, task_id=load_fact_table, run_id=manual__2024-12-05T13:58:01.600232+00:00, execution_date=20241205T135801, start_date=20241205T140312, end_date=20241205T140313
[2024-12-05T15:03:13.074+0100] {taskinstance.py:340} INFO - ::group::Post task execution logs
[2024-12-05T15:03:13.074+0100] {standard_task_runner.py:124} ERROR - Failed to execute job 113 for task load_fact_table ('client'; 89939)
Traceback (most recent call last):
  File "/Users/sijibomijoshua/airflow/airflow_env/lib/python3.11/site-packages/airflow/task/task_runner/standard_task_runner.py", line 117, in _start_by_fork
    ret = args.func(args, dag=self.dag)
          ^^^^^^^^^^^^^^^^^^^^^^^^^^^^^
  File "/Users/sijibomijoshua/airflow/airflow_env/lib/python3.11/site-packages/airflow/cli/cli_config.py", line 49, in command
    return func(*args, **kwargs)
           ^^^^^^^^^^^^^^^^^^^^^
  File "/Users/sijibomijoshua/airflow/airflow_env/lib/python3.11/site-packages/airflow/utils/cli.py", line 116, in wrapper
    return f(*args, **kwargs)
           ^^^^^^^^^^^^^^^^^^
  File "/Users/sijibomijoshua/airflow/airflow_env/lib/python3.11/site-packages/airflow/cli/commands/task_command.py", line 483, in task_run
    task_return_code = _run_task_by_selected_method(args, _dag, ti)
                       ^^^^^^^^^^^^^^^^^^^^^^^^^^^^^^^^^^^^^^^^^^^^
  File "/Users/sijibomijoshua/airflow/airflow_env/lib/python3.11/site-packages/airflow/cli/commands/task_command.py", line 256, in _run_task_by_selected_method
    return _run_raw_task(args, ti)
           ^^^^^^^^^^^^^^^^^^^^^^^
  File "/Users/sijibomijoshua/airflow/airflow_env/lib/python3.11/site-packages/airflow/cli/commands/task_command.py", line 341, in _run_raw_task
    return ti._run_raw_task(
           ^^^^^^^^^^^^^^^^^
  File "/Users/sijibomijoshua/airflow/airflow_env/lib/python3.11/site-packages/airflow/utils/session.py", line 97, in wrapper
    return func(*args, session=session, **kwargs)
           ^^^^^^^^^^^^^^^^^^^^^^^^^^^^^^^^^^^^^^
  File "/Users/sijibomijoshua/airflow/airflow_env/lib/python3.11/site-packages/airflow/models/taskinstance.py", line 3005, in _run_raw_task
    return _run_raw_task(
           ^^^^^^^^^^^^^^
  File "/Users/sijibomijoshua/airflow/airflow_env/lib/python3.11/site-packages/airflow/models/taskinstance.py", line 273, in _run_raw_task
    TaskInstance._execute_task_with_callbacks(
  File "/Users/sijibomijoshua/airflow/airflow_env/lib/python3.11/site-packages/airflow/models/taskinstance.py", line 3159, in _execute_task_with_callbacks
    result = self._execute_task(context, task_orig)
             ^^^^^^^^^^^^^^^^^^^^^^^^^^^^^^^^^^^^^^
  File "/Users/sijibomijoshua/airflow/airflow_env/lib/python3.11/site-packages/airflow/models/taskinstance.py", line 3183, in _execute_task
    return _execute_task(self, context, task_orig)
           ^^^^^^^^^^^^^^^^^^^^^^^^^^^^^^^^^^^^^^^
  File "/Users/sijibomijoshua/airflow/airflow_env/lib/python3.11/site-packages/airflow/models/taskinstance.py", line 767, in _execute_task
    result = _execute_callable(context=context, **execute_callable_kwargs)
             ^^^^^^^^^^^^^^^^^^^^^^^^^^^^^^^^^^^^^^^^^^^^^^^^^^^^^^^^^^^^^
  File "/Users/sijibomijoshua/airflow/airflow_env/lib/python3.11/site-packages/airflow/models/taskinstance.py", line 733, in _execute_callable
    return ExecutionCallableRunner(
           ^^^^^^^^^^^^^^^^^^^^^^^^
  File "/Users/sijibomijoshua/airflow/airflow_env/lib/python3.11/site-packages/airflow/utils/operator_helpers.py", line 252, in run
    return self.func(*args, **kwargs)
           ^^^^^^^^^^^^^^^^^^^^^^^^^^
  File "/Users/sijibomijoshua/airflow/airflow_env/lib/python3.11/site-packages/airflow/models/baseoperator.py", line 417, in wrapper
    return func(self, *args, **kwargs)
           ^^^^^^^^^^^^^^^^^^^^^^^^^^^
  File "/Users/sijibomijoshua/airflow/airflow_env/lib/python3.11/site-packages/airflow/operators/python.py", line 238, in execute
    return_value = self.execute_callable()
                   ^^^^^^^^^^^^^^^^^^^^^^^
  File "/Users/sijibomijoshua/airflow/airflow_env/lib/python3.11/site-packages/airflow/operators/python.py", line 256, in execute_callable
    return runner.run(*self.op_args, **self.op_kwargs)
           ^^^^^^^^^^^^^^^^^^^^^^^^^^^^^^^^^^^^^^^^^^^
  File "/Users/sijibomijoshua/airflow/airflow_env/lib/python3.11/site-packages/airflow/utils/operator_helpers.py", line 252, in run
    return self.func(*args, **kwargs)
           ^^^^^^^^^^^^^^^^^^^^^^^^^^
  File "/Users/sijibomijoshua/airflow/dags/dim_process.py", line 147, in load_fact_table
    raise e
  File "/Users/sijibomijoshua/airflow/dags/dim_process.py", line 123, in load_fact_table
    merged_df = merged_df.merge(
                ^^^^^^^^^^^^^^^^
  File "/Users/sijibomijoshua/airflow/airflow_env/lib/python3.11/site-packages/pandas/core/frame.py", line 10832, in merge
    return merge(
           ^^^^^^
  File "/Users/sijibomijoshua/airflow/airflow_env/lib/python3.11/site-packages/pandas/core/reshape/merge.py", line 170, in merge
    op = _MergeOperation(
         ^^^^^^^^^^^^^^^^
  File "/Users/sijibomijoshua/airflow/airflow_env/lib/python3.11/site-packages/pandas/core/reshape/merge.py", line 794, in __init__
    ) = self._get_merge_keys()
        ^^^^^^^^^^^^^^^^^^^^^^
  File "/Users/sijibomijoshua/airflow/airflow_env/lib/python3.11/site-packages/pandas/core/reshape/merge.py", line 1310, in _get_merge_keys
    left_keys.append(left._get_label_or_level_values(lk))
                     ^^^^^^^^^^^^^^^^^^^^^^^^^^^^^^^^^^^
  File "/Users/sijibomijoshua/airflow/airflow_env/lib/python3.11/site-packages/pandas/core/generic.py", line 1911, in _get_label_or_level_values
    raise KeyError(key)
KeyError: 'client'
[2024-12-05T15:03:13.093+0100] {local_task_job_runner.py:266} INFO - Task exited with return code 1
[2024-12-05T15:03:13.098+0100] {taskinstance.py:3895} INFO - 0 downstream tasks scheduled from follow-on schedule check
[2024-12-05T15:03:13.098+0100] {local_task_job_runner.py:245} INFO - ::endgroup::
